<?xml version="1.0" ?>
<!-- =================================================================================== -->
<!-- |    This document was autogenerated by xacro from wx200.urdf.xacro               | -->
<!-- |    EDITING THIS FILE BY HAND IS NOT RECOMMENDED                                 | -->
<!-- =================================================================================== -->
<robot name="wx200" xmlns:xacro="http://ros.org/wiki/xacro">
  <material name="interbotix_black">
    <texture filename="../meshes/interbotix_black.png"/>
    <color rgba="0 0 0 1" />
  </material>
  <link name="/base_link">
    <visual>
      <origin rpy="0 0 1.57079632679" xyz="0 0 0"/>
      <geometry>
        <mesh filename="../meshes/meshes_wx200/WXA-200-M-1-Base.stl" scale="0.001 0.001 0.001"/>
      </geometry>
      <material name="interbotix_black"/>
    </visual>
    <collision>
      <origin rpy="0 0 1.57079632679" xyz="0 0 0"/>
      <geometry>
        <mesh filename="../meshes/meshes_wx200/WXA-200-M-1-Base.stl" scale="0.001 0.001 0.001"/>
      </geometry>
    </collision>
    <inertial>
      <origin rpy="0 0 1.57079632679" xyz="-0.0381747000 0.0006478630 0.0193458000"/>
      <mass value="100.540142"/>
      <inertia ixx="0.0021190000" ixy="-0.0000172100" ixz="0.0000006389" iyy="0.0006925000" iyz="0.0000461200" izz="0.0025280000"/>
    </inertial>
  </link>
  <joint name="waist" type="revolute">
    <axis xyz="0 0 1"/>
    <limit effort="100" lower="-3.14159265359" upper="3.14159265359" velocity="3.14159265359"/>
    <origin rpy="0 0 0" xyz="0 0 0.0716"/>
    <parent link="/base_link"/>
    <child link="/shoulder_link"/>
  </joint>
  <transmission name="trans_waist">
    <type>transmission_interface/SimpleTransmission</type>
    <joint name="waist">
      <hardwareInterface>hardware_interface/EffortJointInterface</hardwareInterface>
    </joint>
    <actuator name="waist_motor">
      <mechanicalReduction>1</mechanicalReduction>
    </actuator>
  </transmission>
  <link name="/shoulder_link">
    <visual>
      <origin rpy="0 0 1.57079632679" xyz="0 0 -0.003"/>
      <geometry>
        <mesh filename="../meshes/meshes_wx200/WXA-200-M-2-Shoulder.stl" scale="0.001 0.001 0.001"/>
      </geometry>
      <material name="interbotix_black"/>
    </visual>
    <collision>
      <origin rpy="0 0 1.57079632679" xyz="0 0 -0.003"/>
      <geometry>
        <mesh filename="../meshes/meshes_wx200/WXA-200-M-2-Shoulder.stl" scale="0.001 0.001 0.001"/>
      </geometry>
    </collision>
    <inertial>
      <origin rpy="0 0 1.57079632679" xyz="0.0000223210 0.0000414608 0.0066287000"/>
      <mass value="0.480879"/>
      <inertia ixx="0.0003790000" ixy="0.0000000022" ixz="-0.0000003561" iyy="0.0005557000" iyz="0.0000012247" izz="0.0005889000"/>
    </inertial>
  </link>
  <joint name="shoulder" type="revolute">
    <axis xyz="0 1 0"/>
    <limit effort="100" lower="-1.88495559215" upper="1.97222205475" velocity="3.14159265359"/>
    <origin rpy="0 0 0" xyz="0 0 0.03865"/>
    <parent link="/shoulder_link"/>
    <child link="/upper_arm_link"/>
  </joint>
  <transmission name="trans_shoulder">
    <type>transmission_interface/SimpleTransmission</type>
    <joint name="shoulder">
      <hardwareInterface>hardware_interface/EffortJointInterface</hardwareInterface>
    </joint>
    <actuator name="shoulder_motor">
      <mechanicalReduction>1</mechanicalReduction>
    </actuator>
  </transmission>
  <link name="/upper_arm_link">
    <visual>
      <origin rpy="0 0 1.57079632679" xyz="0 0 0"/>
      <geometry>
        <mesh filename="../meshes/meshes_wx200/WXA-200-M-3-UA.stl" scale="0.001 0.001 0.001"/>
      </geometry>
      <material name="interbotix_black"/>
    </visual>
    <collision>
      <origin rpy="0 0 1.57079632679" xyz="0 0 0"/>
      <geometry>
        <mesh filename="../meshes/meshes_wx200/WXA-200-M-3-UA.stl" scale="0.001 0.001 0.001"/>
      </geometry>
    </collision>
    <inertial>
      <origin rpy="0 0 1.57079632679" xyz="0.0119707000 -0.0001179264 0.1394290000"/>
      <mass value="0.297781"/>
      <inertia ixx="0.0017100000" ixy="-0.0000011433" ixz="0.0000021161" iyy="0.0016310000" iyz="0.0002135000" izz="0.0001482000"/>
    </inertial>
  </link>
  <joint name="elbow" type="revolute">
    <axis xyz="0 1 0"/>
    <limit effort="100" lower="-1.62315620435" upper="1.88495559215" velocity="3.14159265359"/>
    <origin rpy="3.14159265359 0 0" xyz="0.05 0 0.2"/>
    <parent link="/upper_arm_link"/>
    <child link="/forearm_link"/>
  </joint>
  <transmission name="trans_elbow">
    <type>transmission_interface/SimpleTransmission</type>
    <joint name="elbow">
      <hardwareInterface>hardware_interface/EffortJointInterface</hardwareInterface>
    </joint>
    <actuator name="elbow_motor">
      <mechanicalReduction>1</mechanicalReduction>
    </actuator>
  </transmission>
  <link name="/forearm_link">
    <visual>
      <origin rpy="0 0 1.57079632679" xyz="0 0 0"/>
      <geometry>
        <mesh filename="../meshes/meshes_wx200/WXA-200-M-4-Forearm.stl" scale="0.001 0.001 0.001"/>
      </geometry>
      <material name="interbotix_black"/>
    </visual>
    <collision>
      <origin rpy="0 0 1.57079632679" xyz="0 0 0"/>
      <geometry>
        <mesh filename="../meshes/meshes_wx200/WXA-200-M-4-Forearm.stl" scale="0.001 0.001 0.001"/>
      </geometry>
    </collision>
    <inertial>
      <origin rpy="0 0 1.57079632679" xyz="0.1211920000 -0.0001238123 0.0000000000"/>
      <mass value="0.283651"/>
      <inertia ixx="0.0011850000" ixy="-0.0000024317" ixz="0.0000000000" iyy="0.0000682900" iyz="0.0000000000" izz="0.0012060000"/>
    </inertial>
  </link>
  <joint name="wrist_angle" type="revolute">
    <axis xyz="0 1 0"/>
    <limit effort="100" lower="-2.14675497995" upper="1.74532925199" velocity="3.14159265359"/>
    <origin rpy="0 0 0" xyz="0.2 0 0"/>
    <parent link="/forearm_link"/>
    <child link="/wrist_link"/>
  </joint>
  <transmission name="trans_wrist_angle">
    <type>transmission_interface/SimpleTransmission</type>
    <joint name="wrist_angle">
      <hardwareInterface>hardware_interface/EffortJointInterface</hardwareInterface>
    </joint>
    <actuator name="wrist_angle_motor">
      <mechanicalReduction>1</mechanicalReduction>
    </actuator>
  </transmission>
  <link name="/wrist_link">
    <visual>
      <origin rpy="0 3.14159265359 1.57079632679" xyz="0 0 0"/>
      <geometry>
        <mesh filename="../meshes/meshes_wx200/WXA-200-M-5-Wrist.stl" scale="0.001 0.001 0.001"/>
      </geometry>
      <material name="interbotix_black"/>
    </visual>
    <collision>
      <origin rpy="0 3.14159265359 1.57079632679" xyz="0 0 0"/>
      <geometry>
        <mesh filename="../meshes/meshes_wx200/WXA-200-M-5-Wrist.stl" scale="0.001 0.001 0.001"/>
      </geometry>
    </collision>
    <inertial>
      <origin rpy="0 3.14159265359 1.57079632679" xyz="0.0423600000 0.0000106630 -0.0105770000"/>
      <mass value="0.084957"/>
      <inertia ixx="0.0000308200" ixy="0.0000000191" ixz="0.0000000023" iyy="0.0000282200" iyz="0.0000025481" izz="0.0000315200"/>
    </inertial>
  </link>
  <joint name="wrist_rotate" type="revolute">
    <axis xyz="1 0 0"/>
    <limit effort="100" lower="-3.14159265359" upper="3.14159265359" velocity="3.14159265359"/>
    <origin rpy="-3.14159265359 0 0" xyz="0.065 0 0"/>
    <parent link="/wrist_link"/>
    <child link="/gripper_link"/>
  </joint>
  <transmission name="trans_wrist_rotate">
    <type>transmission_interface/SimpleTransmission</type>
    <joint name="wrist_rotate">
      <hardwareInterface>hardware_interface/EffortJointInterface</hardwareInterface>
    </joint>
    <actuator name="wrist_rotate_motor">
      <mechanicalReduction>1</mechanicalReduction>
    </actuator>
  </transmission>
  <link name="/gripper_link">
    <visual>
      <origin rpy="0 0 1.57079632679" xyz="-0.02 0 0"/>
      <geometry>
        <mesh filename="../meshes/meshes_wx200/WXA-200-M-6-Gripper.stl" scale="0.001 0.001 0.001"/>
      </geometry>
      <material name="interbotix_black"/>
    </visual>
    <collision>
      <origin rpy="0 0 1.57079632679" xyz="-0.02 0 0"/>
      <geometry>
        <mesh filename="../meshes/meshes_wx200/WXA-200-M-6-Gripper.stl" scale="0.001 0.001 0.001"/>
      </geometry>
    </collision>
    <inertial>
      <origin rpy="0 0 1.57079632679" xyz="0.0216310000 0.0000002516 0.0114100000"/>
      <mass value="0.072885"/>
      <inertia ixx="0.0000253700" ixy="0.0000000000" ixz="0.0000000000" iyy="0.0000183600" iyz="0.0000004340" izz="0.0000167400"/>
    </inertial>
  </link>
  <joint name="ee_arm" type="fixed">
    <axis xyz="1 0 0"/>
    <origin rpy="0 0 0" xyz="0.043 0 0"/>
    <parent link="/gripper_link"/>
    <child link="/ee_arm_link"/>
  </joint>
  <link name="/ee_arm_link">
    <inertial>
      <mass value="0.001"/>
      <inertia ixx="0.001" ixy="0" ixz="0" iyy="0.001" iyz="0" izz="0.001"/>
    </inertial>
  </link>
</robot>
